#VRML_SIM R2025a utf8

EXTERNPROTO "https://raw.githubusercontent.com/cyberbotics/webots/R2025a/projects/objects/backgrounds/protos/TexturedBackground.proto"
EXTERNPROTO "https://raw.githubusercontent.com/cyberbotics/webots/R2025a/projects/objects/backgrounds/protos/TexturedBackgroundLight.proto"
EXTERNPROTO "https://raw.githubusercontent.com/cyberbotics/webots/R2025a/projects/objects/floors/protos/RectangleArena.proto"
EXTERNPROTO "https://raw.githubusercontent.com/cyberbotics/webots/R2025a/projects/appearances/protos/BrushedAluminium.proto"
EXTERNPROTO "https://raw.githubusercontent.com/cyberbotics/webots/R2025a/projects/appearances/protos/Parquetry.proto"
EXTERNPROTO "https://raw.githubusercontent.com/cyberbotics/webots/R2025a/projects/objects/bedroom/protos/Bed.proto"
EXTERNPROTO "https://raw.githubusercontent.com/cyberbotics/webots/R2025a/projects/objects/cabinet/protos/Cabinet.proto"
EXTERNPROTO "https://raw.githubusercontent.com/cyberbotics/webots/R2025a/projects/objects/tables/protos/Desk.proto"
EXTERNPROTO "https://raw.githubusercontent.com/cyberbotics/webots/R2025a/projects/objects/tables/protos/Table.proto"
EXTERNPROTO "https://raw.githubusercontent.com/cyberbotics/webots/R2025a/projects/objects/chairs/protos/OfficeChair.proto"
EXTERNPROTO "https://raw.githubusercontent.com/cyberbotics/webots/R2025a/projects/objects/chairs/protos/Chair.proto"
EXTERNPROTO "https://raw.githubusercontent.com/cyberbotics/webots/R2025a/projects/objects/bathroom/protos/Bathtube.proto"
EXTERNPROTO "https://raw.githubusercontent.com/cyberbotics/webots/R2025a/projects/objects/bathroom/protos/Toilet.proto"
EXTERNPROTO "https://raw.githubusercontent.com/cyberbotics/webots/R2025a/projects/objects/kitchen/fridge/protos/Fridge.proto"
EXTERNPROTO "https://raw.githubusercontent.com/cyberbotics/webots/R2025a/projects/objects/apartment_structure/protos/Window.proto"
EXTERNPROTO "https://raw.githubusercontent.com/cyberbotics/webots/R2025a/projects/objects/apartment_structure/protos/Wall.proto"
EXTERNPROTO "https://raw.githubusercontent.com/cyberbotics/webots/R2025a/projects/objects/living_room_furniture/protos/Sofa.proto"
EXTERNPROTO "https://raw.githubusercontent.com/cyberbotics/webots/R2025a/projects/objects/living_room_furniture/protos/Armchair.proto"
EXTERNPROTO "https://raw.githubusercontent.com/cyberbotics/webots/R2025a/projects/objects/plants/protos/PottedTree.proto"
EXTERNPROTO "https://raw.githubusercontent.com/cyberbotics/webots/R2025a/projects/objects/television/protos/Television.proto"

WorldInfo {
}
Viewpoint {
  orientation 0.6319986248518905 0.007023016723748984 -0.7749376848633814 3.124365781877455
  position 1.3582369854571523 1.3082854929128154 19.444183944115153
}
TexturedBackground {
}
TexturedBackgroundLight {
}
RectangleArena {
  translation -1.7 0.27 0
  floorSize 11 17
  floorAppearance Parquetry {
    type "light strip"
  }
  wallHeight 0.5
  wallAppearance BrushedAluminium {
    IBLStrength 0
  }
}
Robot {
  translation 8.212113891010521e-08 -2.976189017628035e-06 -0.026182133553899978
  rotation -9.82127789083848e-06 1.0458362295947007e-05 0.9999999998970827 1.5700000009220134
  children [
    DEF body Pose {
      translation 0 0 0.225
      children [
        Shape {
          appearance PBRAppearance {
            baseColor 0 0 1
            roughness 1
            metalness 0
          }
          geometry Cylinder {
            height 0.4
            radius 0.225
          }
        }
      ]
    }
    HingeJoint {
      jointParameters HingeJointParameters {
        position 323.5198831306825
        anchor 0.225 0 0.125
      }
      device [
        DEF motor_1 RotationalMotor {
          name "motor_1"
        }
        DEF ps_1 PositionSensor {
          name "ps_1"
        }
      ]
      endPoint Solid {
        translation 0.225 0 0.125
        rotation 0.6995158866273337 -0.1487741567832561 0.6989590650598978 3.4372062844639903
        children [
          Shape {
            appearance PBRAppearance {
              baseColor 0 0 0
              roughness 1
              metalness 0
            }
            geometry Box {
              size 0.025 0.025 0.052
            }
          }
          DEF wheel Shape {
            appearance PBRAppearance {
              baseColor 1 0 0
              roughness 1
              metalness 0
            }
            geometry Cylinder {
              height 0.05
              radius 0.125
            }
          }
        ]
        boundingObject USE wheel
        physics DEF wheel_physics Physics {
        }
        linearVelocity -1.2499475753392453e-07 1.6971790975335131e-06 -8.39574719058329e-06
        angularVelocity -1.938521399790338e-05 -1.1923492494937385e-06 2.530842046624813e-10
      }
    }
    HingeJoint {
      jointParameters HingeJointParameters {
        position 323.53521644681655
        anchor -0.225 0 0.125
      }
      device [
        DEF motor_2 RotationalMotor {
          name "motor_2"
        }
        DEF ps_2 PositionSensor {
          name "ps_2"
        }
      ]
      endPoint Solid {
        translation -0.225 0 0.125
        rotation 0.6995447884404901 -0.1485023343063596 0.6989879438669255 3.4366739854239357
        children [
          Shape {
            appearance PBRAppearance {
              baseColor 0 0 0
              roughness 1
              metalness 0
            }
            geometry Box {
              size 0.025 0.025 0.052
            }
          }
          USE wheel
        ]
        name "solid(1)"
        boundingObject USE wheel
        physics USE wheel_physics
        linearVelocity -1.2463766699037261e-07 1.6951914793188702e-06 1.0322134723763801e-07
        angularVelocity -1.938559641179298e-05 -1.1885053919856794e-06 2.5303652455919945e-10
      }
    }
    Solid {
      translation -2.03924e-08 -0.23 0.21
      rotation 0 0 1 -1.5707953071795862
      children [
        DEF nose Shape {
          appearance PBRAppearance {
            baseColor 0 1 0
            roughness 1
            metalness 0
          }
          geometry Box {
            size 0.015 0.075 0.05
          }
        }
      ]
      name "solid(2)"
    }
    Solid {
      translation 0.025 -0.23 0.28
      children [
        DEF eye Shape {
          appearance PBRAppearance {
            baseColor 0 1 0
            roughness 1
            metalness 0
          }
          geometry Box {
            size 0.025 0.025 0.025
          }
        }
      ]
      name "solid(3)"
    }
    Solid {
      translation -0.025 -0.23 0.28
      children [
        USE eye
      ]
      name "solid(4)"
    }
    Solid {
      translation 0 0 0.44
      children [
        USE eye
      ]
      name "solid(5)"
    }
    Solid {
      translation -0.25 0 0.15
      children [
        USE eye
      ]
      name "solid(7)"
    }
    Solid {
      translation 0.25 0 0.15
      children [
        USE eye
      ]
      name "solid(6)"
    }
    Lidar {
      translation 0 0 0.45
      rotation 0 0 1 -1.5731853071795863
      fieldOfView 6.28
      numberOfLayers 1
      maxRange 4
    }
  ]
  boundingObject USE body
  physics Physics {
  }
  controller "robot_controller"
  linearVelocity -2.8480321651276566e-07 4.581671170189542e-06 -4.229118252203696e-06
  angularVelocity -1.92620600996574e-05 -1.304657010017037e-06 2.537189107805308e-10
}
Bed {
  translation 0.940002 7.2 0
  rotation 0 0 -1 1.5708
  name "bed(1)"
}
Bed {
  translation 0.359953 -6.56 0
  rotation 0 0 1 1.57079
  name "bed(2)"
}
Cabinet {
  hidden position_6_0 6.399798787900102e-06
  hidden translation_7 -2.5471199175088735e-06 -1.6301071603663786e-11 0
  hidden rotation_7 0 0 1 1.279960306356277e-05
  hidden position_10_0 -5.440791833954961e-06
  hidden translation_11 -1.840619877390639e-06 1.0014433726723837e-11 0
  hidden rotation_11 0 0 -0.9999999999999999 1.0881562121360792e-05
  translation -4.74 -4.27 0
}
Cabinet {
  hidden position_6_0 6.399798787900102e-06
  hidden translation_7 -2.5471199175088735e-06 -1.6301071603663786e-11 0
  hidden rotation_7 0 0 1 1.279960306356277e-05
  hidden position_10_0 -5.440791833954961e-06
  hidden translation_11 -1.840619877390639e-06 1.0014433726723837e-11 0
  hidden rotation_11 0 0 -0.9999999999999999 1.0881562121360792e-05
  translation -4.74 -5.09 0
  name "cabinet(2)"
}
Cabinet {
  hidden position_6_0 6.399798787886062e-06
  hidden translation_7 -2.5471199175070935e-06 -1.6301071603663786e-11 0
  hidden rotation_7 0 0 1 1.279960306356277e-05
  hidden position_10_0 -5.440791833954961e-06
  hidden translation_11 -1.840619877390639e-06 1.0014433726723837e-11 0
  hidden rotation_11 0 0 -0.9999999999999999 1.0881562121360792e-05
  translation -1.91 6.72 0
  rotation 0 0 1 -1.5707953071795862
  name "cabinet(1)"
}
Cabinet {
  hidden position_6_0 6.399798787871693e-06
  hidden translation_7 -2.5471199175029363e-06 -1.6301071603663786e-11 0
  hidden rotation_7 0 0 1 1.279960306356277e-05
  hidden position_10_0 -5.440791833954961e-06
  hidden translation_11 -1.840619877390639e-06 1.0014433726723837e-11 0
  hidden rotation_11 0 0 -0.9999999999999999 1.0881562121360792e-05
  translation -1.91 6.83 0
  rotation 0 0 1 1.5708
  name "cabinet(4)"
}
Desk {
  translation -4.86 6.6 0
  rotation 0 0 1 1.01503e-06
}
Table {
  translation -5.78 1.37 0
  rotation 0 0 1 -1.5707953071795862
}
OfficeChair {
  hidden position_0_0 -2.19534207017702e-05
  hidden rotation_1 0 0 1 0.0011103435936266857
  translation -5.439999998241185 6.54984999669508 -0.0014153381261824693
  rotation -0.00621250434029306 -0.9999801988826177 0.0010033107704778893 0.0014054482189747744
}
Chair {
  translation -5.41 0.58 0
  rotation 0 0 1 1.5708
}
Chair {
  translation -6.2 0.6 0
  rotation 0 0 1 1.5708
  name "chair(1)"
}
Chair {
  translation -5.39 2.23 0
  rotation 0 0 1 -1.5707953071795862
  name "chair(2)"
}
Chair {
  translation -6.25 2.19 0
  rotation 0 0 1 -1.5707953071795862
  name "chair(3)"
}
Bathtube {
  translation -6.32 3.8 0
}
Bathtube {
  translation -6.32 -6.65 0
  name "bathtube(1)"
}
Toilet {
  translation -5.5 4.39 0
  rotation 0 0 1 -1.5707953071795862
}
Toilet {
  translation -5.5 -6.09 0
  rotation 0 0 1 -1.5707953071795862
  name "toilet(1)"
}
Fridge {
  hidden position_0_0 -4.390548339804752e-05
  hidden position_0_1 4.3905502892704293e-05
  hidden rotation_1 0 0 -0.9999999999999999 8.781097389929762e-05
  hidden rotation_2 0 0 1 8.781100424328175e-05
  translation -6.55 -3.28 0
}
Fridge {
  hidden position_0_0 -4.390548339804752e-05
  hidden position_0_1 4.3905502892704293e-05
  hidden rotation_1 0 0 -0.9999999999999999 8.781097389929762e-05
  hidden rotation_2 0 0 1 8.781100424328175e-05
  translation -6.55 -2.56 0
  name "fridge(1)"
}
Sofa {
  translation 0.459996 2.72 0
  rotation 0 0 1 -1.5707953071795862
}
PottedTree {
  translation 3.23 2.98 0
}
PottedTree {
  translation -6.52 5.35 0
  name "potted tree(2)"
}
PottedTree {
  translation -3.48 -1.08 0
  name "potted tree(1)"
}
PottedTree {
  translation 1.07 -3.33 0.76
  name "potted tree(3)"
}
PottedTree {
  translation -0.41 -3.31 0.79
  name "potted tree(4)"
}
Armchair {
  translation 2.69103 -4.60929 0
  rotation 0 0 1 -2.3561953071795863
}
Armchair {
  translation 2.58605 4.37813 0
  rotation 0 0 -1 -2.3561953071795863
  name "armchair(1)"
}
Armchair {
  translation -1.40492 1.44716 0
  rotation 0 0 -1 -5.307179586466759e-06
  name "armchair(2)"
}
Armchair {
  translation 1.99508 1.36716 0
  rotation 0 0 1 -3.1415853071795863
  name "armchair(3)"
}
Window {
  translation -6.93 -1.65 0
  size 0.1 1 2.5
}
Window {
  translation -6.93 1.36 0
  name "window(5)"
  size 0.1 1 2.5
}
Window {
  translation -6.93001 6.37 0
  rotation 0 0 1 -3.1415853071795863
  name "window(2)"
  size 0.1 1 2.5
}
Window {
  translation 3.63 5.78 0
  name "window(4)"
  size 0.1 2 2.5
}
Window {
  translation 3.63 2.26 0
  name "window(6)"
  size 0.1 2 2.5
}
Window {
  translation 3.6 -2.65 0
  name "window(7)"
  size 0.1 2 2.5
}
Window {
  translation 3.61 -6.26 0
  name "window(1)"
  size 0.1 2 2.5
}
Wall {
  translation -6.93 -4.9 0
  size 0.1 5.5 2.5
}
Wall {
  translation -4.84 -4.66 0
  name "wall(7)"
  size 0.1 2 2.5
}
Wall {
  translation -3.79 -3.71 0
  rotation 0 0 1 1.5708
  name "wall(15)"
  size 0.1 2 2.5
}
Wall {
  translation 0.9 -3.71 0
  rotation 0 0 1 1.5708
  name "wall(3)"
  size 0.1 5.5 2.5
}
Wall {
  translation 3.61 4.03 0
  name "wall(10)"
  size 0.1 1.5 2.5
}
Wall {
  translation 3.61 -4.51 0
  name "wall(2)"
  size 0.1 1.5 2.5
}
Wall {
  translation -6.93 -0.14 0
  name "wall(1)"
  size 0.1 2 2.5
}
Wall {
  translation -6.93 7.62 0
  name "wall(17)"
  size 0.1 1.5 2.5
}
Wall {
  translation -6.93 3.87 0
  name "wall(20)"
  size 0.1 4 2.5
}
Wall {
  translation -2.4 6.03 0
  name "wall(22)"
  size 0.1 2.5 2.5
}
Wall {
  translation -1.34 7.32 0
  name "wall(23)"
  size 0.1 2 2.5
}
Wall {
  translation -3.83 -2.2 0
  rotation 0 0 1 1.01503e-06
  name "wall(12)"
  size 0.1 3 2.5
}
Wall {
  translation -0.69 -7.71 0
  rotation 0 0 1 -1.5707953071795862
  name "wall(13)"
  size 0.1 8.6 2.5
}
Wall {
  translation 0.57 3.33 0
  rotation 0 0 1 -1.5707953071795862
  name "wall(28)"
  size 0.1 6 2.5
}
Wall {
  translation 1.94 8.34 0
  rotation 0 0 1 -1.5707953071795862
  name "wall(29)"
  size 0.1 3.7 2.5
}
Wall {
  translation -2.84 -3.9 0
  name "wall(26)"
  size 0.1 0.5 2.5
}
Wall {
  translation -3.85 4.53 0
  name "wall(5)"
  size 0.1 0.5 2.5
}
Wall {
  translation -2.38 3.62 0
  name "wall(16)"
  size 0.1 0.5 2.5
}
Wall {
  translation 3.63 1.02 0
  name "wall(11)"
  size 0.1 0.5 2.5
}
Wall {
  translation 3.61 -1.17 0
  name "wall(30)"
  size 0.1 1 2.5
}
Wall {
  translation 3.6 -7.49 0
  name "wall(14)"
  size 0.1 0.5 2.5
}
Wall {
  translation -2.83 -5.64 0
  name "wall(27)"
  size 0.1 1 2.5
}
Wall {
  translation -5.41 2.77 0
  rotation 0 0 1 -1.5707953071795862
  name "wall(18)"
  size 0.1 3 2.5
}
Wall {
  translation -5.15 4.85 0
  rotation 0 0 1 -1.5707953071795862
  name "wall(4)"
  size 0.1 3.5 2.5
}
Wall {
  translation -3.41 8.33 0
  rotation 0 0 1 -1.5707953071795862
  name "wall(19)"
  size 0.1 7 2.5
}
Wall {
  translation -4.88 -5.61 0
  rotation 0 0 1 -1.5707953071795862
  name "wall(6)"
  size 0.1 4 2.5
}
Wall {
  translation -5.97 -7.71 0
  rotation 0 0 1 -1.5707953071795862
  name "wall(8)"
  size 0.1 2 2.5
}
Wall {
  translation -6.39 -3.7 0
  rotation 0 0 1 -1.5707953071795862
  name "wall(21)"
  size 0.1 1 2.5
}
Wall {
  translation -1.86 6.76 0
  rotation 0 0 1 -1.5707953071795862
  name "wall(24)"
  size 0.1 1 2.5
}
Wall {
  translation -1.86 4.84 0
  rotation 0 0 1 -1.5707953071795862
  name "wall(25)"
  size 0.1 1 2.5
}
Wall {
  translation 3.63 7.54 0
  name "wall(9)"
  size 0.1 1.5 2.5
}
Solid {
  translation -6.56 7.11 0
  children [
    Shape {
      appearance PBRAppearance {
        roughness 1
        metalness 0
      }
      geometry Box {
        size 0.5 2.5 1
      }
    }
  ]
}
Solid {
  translation -3.52 -2.55 0
  children [
    Shape {
      appearance PBRAppearance {
        roughness 1
        metalness 0
      }
      geometry Box {
        size 0.5 2.5 1
      }
    }
  ]
  name "solid(8)"
}
Solid {
  translation 3.24 -2.55 0
  children [
    Shape {
      appearance PBRAppearance {
        roughness 1
        metalness 0
      }
      geometry Box {
        size 0.5 2.5 1
      }
    }
  ]
  name "solid(9)"
}
Solid {
  translation -6.56 -1.67 0
  children [
    Shape {
      appearance PBRAppearance {
        roughness 1
        metalness 0
      }
      geometry Box {
        size 0.5 1 1.5
      }
    }
  ]
  name "solid(4)"
}
Solid {
  translation -4.64 4.44 0
  rotation 0 0 1 -1.5707953071795862
  children [
    Shape {
      appearance PBRAppearance {
        roughness 1
        metalness 0
      }
      geometry Box {
        size 0.5 1 1.5
      }
    }
  ]
  name "solid(6)"
}
Solid {
  translation -3.9 -5.96 0
  rotation 0 0 1 -1.5707953071795862
  children [
    Shape {
      appearance PBRAppearance {
        roughness 1
        metalness 0
      }
      geometry Box {
        size 0.5 2 1.5
      }
    }
  ]
  name "solid(7)"
}
Solid {
  translation -4.12 -2.23 0
  children [
    Shape {
      appearance PBRAppearance {
        roughness 1
        metalness 0
      }
      geometry Box {
        size 0.5 3 1.5
      }
    }
  ]
  name "solid(5)"
}
Solid {
  translation -0.16 8.03 0
  children [
    Shape {
      appearance PBRAppearance {
        roughness 1
        metalness 0
      }
      geometry Box {
        size 0.5 0.5 1
      }
    }
  ]
  name "solid(1)"
}
Solid {
  translation 1.5 -7.37 0
  children [
    Shape {
      appearance PBRAppearance {
        roughness 1
        metalness 0
      }
      geometry Box {
        size 0.5 0.5 1
      }
    }
  ]
  name "solid(2)"
}
Solid {
  translation -0.78 -7.37 0
  children [
    Shape {
      appearance PBRAppearance {
        roughness 1
        metalness 0
      }
      geometry Box {
        size 0.5 0.5 1
      }
    }
  ]
  name "solid(3)"
}
Table {
  translation 0.37 -3.13 0
  rotation 0 0 1 -1.5707953071795862
  name "table(1)"
}
Television {
  translation 0.360013 -3.57 1.52
  rotation 0 0 1 1.5708
}
