#VRML_SIM R2025a utf8

EXTERNPROTO "https://raw.githubusercontent.com/cyberbotics/webots/R2025a/projects/objects/backgrounds/protos/TexturedBackground.proto"
EXTERNPROTO "https://raw.githubusercontent.com/cyberbotics/webots/R2025a/projects/objects/backgrounds/protos/TexturedBackgroundLight.proto"
EXTERNPROTO "https://raw.githubusercontent.com/cyberbotics/webots/R2025a/projects/objects/floors/protos/RectangleArena.proto"
EXTERNPROTO "https://raw.githubusercontent.com/cyberbotics/webots/R2025a/projects/appearances/protos/BrushedAluminium.proto"
EXTERNPROTO "https://raw.githubusercontent.com/cyberbotics/webots/R2025a/projects/appearances/protos/Parquetry.proto"
EXTERNPROTO "https://raw.githubusercontent.com/cyberbotics/webots/R2025a/projects/objects/bedroom/protos/Bed.proto"
EXTERNPROTO "https://raw.githubusercontent.com/cyberbotics/webots/R2025a/projects/objects/cabinet/protos/Cabinet.proto"
EXTERNPROTO "https://raw.githubusercontent.com/cyberbotics/webots/R2025a/projects/objects/tables/protos/Desk.proto"
EXTERNPROTO "https://raw.githubusercontent.com/cyberbotics/webots/R2025a/projects/objects/tables/protos/Table.proto"
EXTERNPROTO "https://raw.githubusercontent.com/cyberbotics/webots/R2025a/projects/objects/chairs/protos/OfficeChair.proto"
EXTERNPROTO "https://raw.githubusercontent.com/cyberbotics/webots/R2025a/projects/objects/chairs/protos/Chair.proto"
EXTERNPROTO "https://raw.githubusercontent.com/cyberbotics/webots/R2025a/projects/objects/bathroom/protos/Bathtube.proto"
EXTERNPROTO "https://raw.githubusercontent.com/cyberbotics/webots/R2025a/projects/objects/bathroom/protos/Toilet.proto"
EXTERNPROTO "https://raw.githubusercontent.com/cyberbotics/webots/R2025a/projects/objects/kitchen/fridge/protos/Fridge.proto"
EXTERNPROTO "https://raw.githubusercontent.com/cyberbotics/webots/R2025a/projects/objects/apartment_structure/protos/Window.proto"
EXTERNPROTO "https://raw.githubusercontent.com/cyberbotics/webots/R2025a/projects/objects/apartment_structure/protos/Wall.proto"

WorldInfo {
}
Viewpoint {
  orientation -0.6124344867776375 0.005801176575540069 0.7905000605665703 3.1266218085101327
  position 5.956207594415509 0.5683597955656099 20.251395641523487
}
TexturedBackground {
}
TexturedBackgroundLight {
}
RectangleArena {
  floorSize 10 10
  floorAppearance Parquetry {
    type "light strip"
  }
  wallAppearance BrushedAluminium {
    IBLStrength 0
  }
}
Robot {
  rotation 0 0 1 1.5700000001102514
  children [
    DEF body Pose {
      translation 0 0 0.225
      children [
        Shape {
          appearance PBRAppearance {
            baseColor 0 0 1
            roughness 1
            metalness 0
          }
          geometry Cylinder {
            height 0.4
            radius 0.225
          }
        }
      ]
    }
    HingeJoint {
      jointParameters HingeJointParameters {
        position 319.9588480122262
        anchor 0.225 0 0.125
      }
      device [
        DEF motor_1 RotationalMotor {
          name "motor_1"
        }
        DEF ps_1 PositionSensor {
          name "ps_1"
        }
      ]
      endPoint Solid {
        translation 0.225 0 0.125
        rotation 0 1 0 1.57
        children [
          Shape {
            appearance PBRAppearance {
              baseColor 0 0 0
              roughness 1
              metalness 0
            }
            geometry Box {
              size 0.025 0.025 0.052
            }
          }
          DEF wheel Shape {
            appearance PBRAppearance {
              baseColor 1 0 0
              roughness 1
              metalness 0
            }
            geometry Cylinder {
              height 0.05
              radius 0.125
            }
          }
        ]
        boundingObject USE wheel
        physics DEF wheel_physics Physics {
        }
      }
    }
    HingeJoint {
      jointParameters HingeJointParameters {
        position 319.97494226610377
        anchor -0.225 0 0.125
      }
      device [
        DEF motor_2 RotationalMotor {
          name "motor_2"
        }
        DEF ps_2 PositionSensor {
          name "ps_2"
        }
      ]
      endPoint Solid {
        translation -0.225 0 0.125
        rotation 0 1 0 1.57
        children [
          Shape {
            appearance PBRAppearance {
              baseColor 0 0 0
              roughness 1
              metalness 0
            }
            geometry Box {
              size 0.025 0.025 0.052
            }
          }
          USE wheel
        ]
        name "solid(1)"
        boundingObject USE wheel
        physics USE wheel_physics
      }
    }
    Solid {
      translation -2.03924e-08 -0.23 0.21
      rotation 0 0 1 -1.5707953071795862
      children [
        DEF nose Shape {
          appearance PBRAppearance {
            baseColor 0 1 0
            roughness 1
            metalness 0
          }
          geometry Box {
            size 0.015 0.075 0.05
          }
        }
      ]
      name "solid(2)"
    }
    Solid {
      translation 0.025 -0.23 0.28
      children [
        DEF eye Shape {
          appearance PBRAppearance {
            baseColor 0 1 0
            roughness 1
            metalness 0
          }
          geometry Box {
            size 0.025 0.025 0.025
          }
        }
      ]
      name "solid(3)"
    }
    Solid {
      translation -0.025 -0.23 0.28
      children [
        USE eye
      ]
      name "solid(4)"
    }
    Solid {
      translation 0 0 0.44
      children [
        USE eye
      ]
      name "solid(5)"
    }
    Solid {
      translation -0.25 0 0.15
      children [
        USE eye
      ]
      name "solid(7)"
    }
    Solid {
      translation 0.25 0 0.15
      children [
        USE eye
      ]
      name "solid(6)"
    }
    Lidar {
      translation 0 0 0.45
      rotation 0 0 1 -1.5731853071795863
      horizontalResolution 128
      fieldOfView 1.57
      numberOfLayers 1
    }
  ]
  boundingObject USE body
  physics Physics {
  }
  controller "robot_controller"
}
Bed {
  translation 4.01 -3.82 0
  rotation 0 0 1 1.5708
}
Bed {
  translation 3.81 4.02 0
  rotation 0 0 1 3.14159
  name "bed(1)"
}
Cabinet {
  translation -0.05 -4.27 0
}
Cabinet {
  translation 4.9 1.46 0
  rotation 0 0 1 3.14159
  name "cabinet(1)"
}
Cabinet {
  translation -0.07 -3.43 0
  name "cabinet(2)"
}
Desk {
  translation 0.589998 4.56 0
  rotation 0 0 1 -1.5707953071795862
}
Table {
  translation -2.72 -2.51 0
}
OfficeChair {
  translation 0.68 4.04 -0.00050478
  rotation 0.0006972817409901603 -0.0007075262097696836 0.9999995066022964 1.570800495076824
}
Chair {
  translation -3.4 -2.86 0
}
Chair {
  translation -3.32 -2.13 0
  name "chair(1)"
}
Chair {
  translation -1.95 -2.9 0
  rotation 0 0 1 3.14159
  name "chair(2)"
}
Chair {
  translation -1.97 -2.01 0
  rotation 0 0 1 3.14159
  name "chair(3)"
}
Bathtube {
  translation -4.38 3.95 0
}
Toilet {
  translation -2.82 4.51 0
  rotation 0 0 1 -1.5707953071795862
}
Fridge {
  translation -4.61 -4.6 0
}
Window {
  translation -5 -3 0
  size 0.1 2 2.5
}
Window {
  translation -3.5 5 0
  rotation 0 0 1 1.5708
  name "window(2)"
  size 0.1 1 2.5
}
Window {
  translation -3.5 -5 0
  rotation 0 0 1 1.5708
  name "window(3)"
  size 0.1 1 2.5
}
Window {
  translation 5 -3 0
  name "window(1)"
  size 0.1 2 2.5
}
Window {
  translation 5 3 0
  name "window(4)"
  size 0.1 2 2.5
}
Wall {
  translation -5 -4.5 0
  size 0.1 1 2.5
}
Wall {
  translation 5 -4.5 0
  name "wall(2)"
  size 0.1 1 2.5
}
Wall {
  translation 5 1.5 0
  name "wall(10)"
  size 0.1 1 2.5
}
Wall {
  translation -5 -1.5 0
  name "wall(1)"
  size 0.1 1 2.5
}
Wall {
  translation -5 1.94 0
  name "wall(8)"
  size 0.1 6 2.5
}
Wall {
  translation 3.49 -1.2 0
  rotation 0 0 1 -1.5707953071795862
  name "wall(12)"
  size 0.1 3 2.5
}
Wall {
  translation 3.49 1 0
  rotation 0 0 1 -1.5707953071795862
  name "wall(16)"
  size 0.1 3 2.5
}
Wall {
  translation -1.55 1.01 0
  rotation 0 0 1 -1.5707953071795862
  name "wall(15)"
  size 0.1 3 2.5
}
Wall {
  translation 1.44 4.99 0
  rotation 0 0 1 -1.5707953071795862
  name "wall(17)"
  size 0.1 7 2.5
}
Wall {
  translation 1.43 -4.99 0
  rotation 0 0 1 -1.5707953071795862
  name "wall(13)"
  size 0.1 7 2.5
}
Wall {
  translation 4.98 0 0
  name "wall(11)"
  size 0.1 2 2.5
}
Wall {
  translation -0.1 -3.08 0
  name "wall(14)"
  size 0.1 4 2.5
}
Wall {
  translation -0.1 2.91 0
  name "wall(18)"
  size 0.1 4 2.5
}
Wall {
  translation -4.5 5 0
  rotation 0 0 1 -1.5707953071795862
  name "wall(4)"
  size 0.1 1 2.5
}
Wall {
  translation -4.5 -5 0
  rotation 0 0 1 -1.5707953071795862
  name "wall(6)"
  size 0.1 1 2.5
}
Wall {
  translation -2.5 -5 0
  rotation 0 0 1 -1.5707953071795862
  name "wall(5)"
  size 0.1 1 2.5
}
Wall {
  translation -2.5 5 0
  rotation 0 0 1 -1.5707953071795862
  name "wall(7)"
  size 0.1 1 2.5
}
Wall {
  translation 5 -1.5 0
  name "wall(3)"
  size 0.1 1 2.5
}
Wall {
  translation 5 4.5 0
  name "wall(9)"
  size 0.1 1 2.5
}
