#VRML_SIM R2025a utf8

EXTERNPROTO "https://raw.githubusercontent.com/cyberbotics/webots/R2025a/projects/objects/backgrounds/protos/TexturedBackground.proto"
EXTERNPROTO "https://raw.githubusercontent.com/cyberbotics/webots/R2025a/projects/objects/backgrounds/protos/TexturedBackgroundLight.proto"
EXTERNPROTO "https://raw.githubusercontent.com/cyberbotics/webots/R2025a/projects/objects/floors/protos/RectangleArena.proto"
EXTERNPROTO "https://raw.githubusercontent.com/cyberbotics/webots/R2025a/projects/appearances/protos/BrushedAluminium.proto"
EXTERNPROTO "https://raw.githubusercontent.com/cyberbotics/webots/R2025a/projects/appearances/protos/Parquetry.proto"
EXTERNPROTO "https://raw.githubusercontent.com/cyberbotics/webots/R2025a/projects/objects/apartment_structure/protos/Wall.proto"
EXTERNPROTO "https://raw.githubusercontent.com/cyberbotics/webots/R2025a/projects/objects/apartment_structure/protos/Window.proto"
EXTERNPROTO "https://raw.githubusercontent.com/cyberbotics/webots/R2025a/projects/objects/apartment_structure/protos/Door.proto"

WorldInfo {
}
Viewpoint {
  orientation -0.5530016173955593 -0.013673945190974042 0.8330679650429547 3.1827901053442997
  position 3.7696931204740776 -0.3586084400534842 8.489520700733099
}
TexturedBackground {
}
TexturedBackgroundLight {
}
RectangleArena {
  floorSize 4 4
  floorAppearance Parquetry {
    type "light strip"
  }
  wallAppearance BrushedAluminium {
    IBLStrength 0
  }
}
Robot {
  translation -1.27798 0.00112391 -0.0473533
  rotation -0.014471494365744884 -0.014465404294290263 0.9997906420493368 1.5701328244136155
  children [
    DEF body Pose {
      translation 0 0 0.0415
      children [
        Shape {
          appearance PBRAppearance {
            baseColor 0 0 1
            roughness 1
            metalness 0
          }
          geometry Cylinder {
            height 0.08
            radius 0.045
          }
        }
      ]
    }
    HingeJoint {
      jointParameters HingeJointParameters {
        position 310.41883281781753
        anchor 0.045 0 0.025
      }
      device [
        DEF motor_1 RotationalMotor {
          name "motor_1"
        }
        DEF ps_1 PositionSensor {
          name "ps_1"
        }
      ]
      endPoint Solid {
        translation 0.045 0 0.025
        rotation -0.6911272310233216 -0.213181700843807 -0.6905770869087517 3.5619926373954542
        children [
          DEF wheel Shape {
            appearance PBRAppearance {
              baseColor 1 0 0
              roughness 1
              metalness 0
            }
            geometry Cylinder {
              height 0.01
              radius 0.025
            }
          }
        ]
        boundingObject USE wheel
        physics DEF wheel_physics Physics {
        }
      }
    }
    HingeJoint {
      jointParameters HingeJointParameters {
        position 310.4188420066952
        anchor -0.045 0 0.025
      }
      device [
        DEF motor_2 RotationalMotor {
          name "motor_2"
        }
        DEF ps_2 PositionSensor {
          name "ps_2"
        }
      ]
      endPoint Solid {
        translation -0.045 0 0.025
        rotation -0.6911277430357069 -0.21317838360771524 -0.6905775985135716 3.561986286709542
        children [
          USE wheel
        ]
        name "solid(1)"
        boundingObject USE wheel
        physics USE wheel_physics
      }
    }
    Solid {
      translation 0 -0.045 0.05
      children [
        DEF nose Shape {
          appearance PBRAppearance {
            baseColor 0 1 0
            roughness 1
            metalness 0
          }
          geometry Box {
            size 0.015 0.005 0.01
          }
        }
      ]
      name "solid(2)"
    }
    Solid {
      translation 0.015 -0.045 0.07
      children [
        DEF eye Shape {
          appearance PBRAppearance {
            baseColor 0 1 0
            roughness 1
            metalness 0
          }
          geometry Box {
            size 0.005 0.005 0.005
          }
        }
      ]
      name "solid(3)"
    }
    Solid {
      translation -0.015 -0.045 0.07
      children [
        USE eye
      ]
      name "solid(4)"
    }
    Solid {
      translation 0 0 0.082
      children [
        USE eye
      ]
      name "solid(5)"
    }
    Lidar {
      translation 0 0 0.084
      rotation 0 0 1 -1.5731853071795863
      horizontalResolution 128
      fieldOfView 1.57
      numberOfLayers 1
    }
  ]
  boundingObject USE body
  physics Physics {
  }
  controller "robot_controller"
}
Wall {
  translation 2 -1 0
  size 0.1 2 1
}
Wall {
  translation 0 -0.5 0
  name "wall(9)"
  size 0.1 3 1
}
Wall {
  translation 2 1.5 0
  name "wall(1)"
  size 0.1 1 1
}
Wall {
  translation -2 1.5 0
  name "wall(8)"
  size 0.1 1 1
}
Wall {
  translation -2 -1.5 0
  name "wall(10)"
  size 0.1 1 1
}
Wall {
  translation 0 2 0
  rotation 0 0 1 1.5707996938995747
  name "wall(2)"
  size 0.1 0.5 1
}
Wall {
  translation 1.88894e-05 -2 0
  rotation 0 0 1 1.5707996938995747
  name "wall(6)"
  size 0.1 0.5 1
}
Wall {
  translation 1.6 2 0
  rotation 0 0 1 1.5707996938995747
  name "wall(3)"
  size 0.1 0.75 1
}
Wall {
  translation 1.5 0 0
  rotation 0 0 1 1.5707996938995747
  name "wall(11)"
  size 0.1 1 1
}
Wall {
  translation 1.6 -2 0
  rotation 0 0 1 1.5707996938995747
  name "wall(7)"
  size 0.1 0.75 1
}
Wall {
  translation -1.6 2 0
  rotation 0 0 1 1.5707996938995747
  name "wall(4)"
  size 0.1 0.75 1
}
Wall {
  translation -1.6 -2 0
  rotation 0 0 1 1.5707996938995747
  name "wall(5)"
  size 0.1 0.75 1
}
Window {
  translation -0.75 2 0
  rotation 0 0 1 1.5707996938995747
  size 0.1 1 1
  bottomWallHeight 0.3
  windowHeight 0.5
  frameSize 0.01 0.02 0.05
  windowSillSize 0.1 0.03
}
Window {
  translation -0.749988 -2 0
  rotation 0 0 1 1.5707996938995747
  name "window(3)"
  size 0.1 1 1
  bottomWallHeight 0.3
  windowHeight 0.5
  frameSize 0.01 0.02 0.05
  windowSillSize 0.1 0.03
}
Window {
  translation 0.75 2 0
  rotation 0 0 1 1.5707996938995747
  name "window(2)"
  size 0.1 1 1
  bottomWallHeight 0.3
  windowHeight 0.5
  frameSize 0.01 0.02 0.05
  windowSillSize 0.1 0.03
}
Window {
  translation 0.750014 -2 0
  rotation 0 0 1 1.5707996938995747
  name "window(4)"
  size 0.1 1 1
  bottomWallHeight 0.3
  windowHeight 0.5
  frameSize 0.01 0.02 0.05
  windowSillSize 0.1 0.03
}
Window {
  translation 2 0.25 0
  name "window(1)"
  size 0.1 0.5 1
  bottomWallHeight 0.3
  windowHeight 0.5
  frameSize 0.01 0.02 0.05
  windowSillSize 0.1 0.03
}
Window {
  translation -2 0 0
  name "window(5)"
  size 0.1 2 1
  bottomWallHeight 0.3
  windowHeight 0.5
  frameSize 0.01 0.02 0.05
  windowSillSize 0.1 0.03
}
Door {
  hidden translation_4 0.0010173140033830352 4.1688474393952735e-06 -3.3306690738754696e-16
  hidden rotation_4 0 0 -1 7.066879741935132e-05
  translation 2 0.75 0
  size 0.1 0.5 1
  position -7.066880029448283e-05
  frameSize 0.01 0.01 0.01
}
Solid {
  translation 0.8 -1.15 0.049607554431792274
  rotation 0.5404048380776905 -0.6755060475971333 -0.5016514633108573 6.311203918492863e-17
  children [
    Solid {
      translation 0.7 -0.04 -8.44708e-07
      rotation 2.3464099999870814e-06 2.3464099999870814e-06 0.9999999999944944 1.5708
      children [
        Shape {
          appearance PBRAppearance {
            baseColor 1 0 0
            metalness 0
          }
          geometry Box {
            size 0.9 0.6 0.4
          }
        }
      ]
    }
    Solid {
      translation 0.7 -0.55 0
      rotation 0 0 1 -1.5707953071795862
      children [
        Shape {
          appearance PBRAppearance {
            metalness 0
          }
          geometry Box {
            size 0.1 0.6 0.4
          }
        }
      ]
      name "solid(1)"
    }
  ]
  boundingObject Box {
    size 0.1 0.1 0.1
  }
  physics Physics {
  }
  linearVelocity 9.48024474338869e-18 -8.656721772312354e-17 3.5687503744668833e-07
  angularVelocity 1.5987211554602245e-15 -3.944304526105059e-31 -1.7245939569365588e-16
}
